<?xml version="1.0"?>
<robot name="titan" xmlns:xacro="http://www.ros.org/wiki/xacro">

  <!-- RVIZ colors -->
  <material name="black">
    <color rgba="0.0 0.0 0.0 1.0"/>
  </material>
  <material name="blue">
    <color rgba="0.0 0.0 0.8 1.0"/>
  </material>
  <material name="green">
    <color rgba="0.0 0.8 0.0 1.0"/>
  </material>
  <material name="grey">
    <color rgba="0.2 0.2 0.2 1.0"/>
  </material>
  <material name="orange">
    <color rgba="1.0 0.423529411765 0.0392156862745 1.0"/>
  </material>
  <material name="brown">
    <color rgba="0.870588235294 0.811764705882 0.764705882353 1.0"/>
  </material>
  <material name="red">
    <color rgba="0.8 0.0 0.0 1.0"/>
  </material>
  <material name="white">
    <color rgba="1.0 1.0 1.0 1.0"/>
  </material>

  <!--BASE LINK-->
  <gazebo reference="base_link">
    <material>Gazebo/Grey</material>
  </gazebo>
  <link name="base_link">
    <collision>
      <geometry>
        <box size="0.5334 0.3683 0.1016"/>
      </geometry>
    </collision>
    <visual>
      <geometry>
        <box size="0.5334 0.3683 0.1016"/>
      </geometry>
      <material name="grey"/>
    </visual>
    <inertial>
      <origin xyz="0 0 1" rpy="0 0 0"/>
      <mass value="1"/>
      <inertia ixx="1.0" ixy="0.0" ixz="0.0" iyy="1.0" iyz="0.0" izz="1.0"/>
    </inertial>
  </link>


  <!--TOP BOX LINK-->
  <gazebo reference="top_box">
    <material>Gazebo/Grey</material>
  </gazebo>
  <link name="top_box">
    <collision>
      <geometry>
        <box size="0.254 0.254 0.0889"/>
      </geometry>
      <origin rpy="0 0 0" xyz="0 0 0"/>
    </collision>
    <visual>
      <geometry>
        <box size="0.254 0.254 0.0889"/>
      </geometry>
      <origin rpy="0 0 0" xyz="0 0 0"/>
      <material name="grey"/>
    </visual>
    <inertial>
      <origin xyz="0 0 1" rpy="0 0 0"/>
      <mass value="1"/>
      <inertia ixx="1.0" ixy="0.0" ixz="0.0" iyy="1.0" iyz="0.0" izz="1.0"/>
    </inertial>
  </link>
  <joint name="base_to_top_box" type="fixed">
    <parent link="base_link"/>
    <child link="top_box"/>
    <origin xyz="-0.0508 0 0.1016"/>
  </joint>

  <!--LEFT FRONT WHEEL-->
  <gazebo reference="left_front_wheel">
    <mu1 value="200.0"/>
    <mu2 value="100.0"/>
    <kp value="10000000.0"/>
    <kd value="1.0"/>
    <material>Gazebo/Black</material>
  </gazebo>
  <transmission name="left_front_wheel_trans">
    <type>transmission_interface/SimpleTransmission</type>
    <joint name="left_front_wheel_joint">
      <hardwareInterface>VelocityJointInterface</hardwareInterface>
    </joint>
    <actuator name="left_front_wheel_motor">
      <mechanicalReduction>1</mechanicalReduction>
    </actuator>
  </transmission>
  <link name="left_front_wheel">
    <collision>
      <geometry>
        <cylinder radius="0.127" length="0.0889"/>
      </geometry>
      <origin rpy="1.57075 0 0" xyz="0 0 0"/>
    </collision>
    <visual>
      <geometry>
        <cylinder radius="0.127" length="0.0889"/>
      </geometry>
      <origin rpy="1.57075 0 0" xyz="0 0 0"/>
      <material name="black"/>
    </visual>
    <inertial>
      <mass value="1"/>
      <inertia ixx="1.0" ixy="0.0" ixz="0.0" iyy="1.0" iyz="0.0" izz="1.0"/>
    </inertial>
  </link>
  <joint name="left_front_wheel_joint" type="continuous">
    <axis rpy="0 0 0" xyz="0 1 0"/>
    <parent link="base_link"/>
    <child link="left_front_wheel"/>
    <origin xyz="0.23 0.2286 0.0"/>
  </joint>

  <!--LEFT BACK WHEEL-->
  <gazebo reference="left_back_wheel">
    <mu1 value="200.0"/>
    <mu2 value="100.0"/>
    <kp value="10000000.0"/>
    <kd value="1.0"/>
    <material>Gazebo/Black</material>
  </gazebo>
  <transmission name="left_back_wheel_trans">
    <type>transmission_interface/SimpleTransmission</type>
    <joint name="left_back_wheel_joint">
      <hardwareInterface>VelocityJointInterface</hardwareInterface>
    </joint>
    <actuator name="left_back_wheel_motor">
      <mechanicalReduction>1</mechanicalReduction>
    </actuator>
  </transmission>
  <link name="left_back_wheel">
    <collision>
      <geometry>
        <cylinder radius="0.127" length="0.0889"/>
      </geometry>
      <origin rpy="1.57075 0 0" xyz="0 0 0"/>
    </collision>
    <visual>
      <geometry>
        <cylinder radius="0.127" length="0.0889"/>
      </geometry>
      <origin rpy="1.57075 0 0" xyz="0 0 0"/>
      <material name="black"/>
    </visual>
    <inertial>
      <mass value="1"/>
      <inertia ixx="1.0" ixy="0.0" ixz="0.0" iyy="1.0" iyz="0.0" izz="1.0"/>
    </inertial>
  </link>
  <joint name="left_back_wheel_joint" type="continuous">
    <axis rpy="0 0 0" xyz="0 1 0"/>
    <parent link="base_link"/>
    <child link="left_back_wheel"/>
    <origin xyz="-0.23 0.2286 0.0"/>
  </joint>

  <!--RIGHT FRONT WHEEL -->
  <link name="right_front_wheel">
    <collision>
      <geometry>
        <cylinder radius="0.127" length="0.0889"/>
      </geometry>
      <origin rpy="1.57075 0 0" xyz="0 0 0"/>
    </collision>
    <visual>
      <geometry>
        <cylinder radius="0.127" length="0.0889"/>
      </geometry>
      <origin rpy="1.57075 0 0" xyz="0 0 0"/>
      <material name="black"/>
    </visual>
    <inertial>
      <mass value="1"/>
      <inertia ixx="1.0" ixy="0.0" ixz="0.0" iyy="1.0" iyz="0.0" izz="1.0"/>
    </inertial>
  </link>
  <joint name="right_front_wheel_joint" type="continuous">
    <axis rpy="0 0 0" xyz="0 1 0"/>
    <parent link="base_link"/>
    <child link="right_front_wheel"/>
    <origin xyz="0.23 -0.2286 0.0"/>
  </joint>
  <gazebo reference="right_front_wheel">
    <mu1 value="200.0"/>
    <mu2 value="100.0"/>
    <kp value="10000000.0"/>
    <kd value="1.0"/>
    <material>Gazebo/Black</material>
  </gazebo>
  <transmission name="right_front_wheel_trans">
    <type>transmission_interface/SimpleTransmission</type>
    <joint name="right_front_wheel_joint">
      <hardwareInterface>VelocityJointInterface</hardwareInterface>
    </joint>
    <actuator name="right_front_wheel_motor">
      <mechanicalReduction>1</mechanicalReduction>
    </actuator>
  </transmission>


  <!--RIGHT BACK WHEEL-->
  <gazebo reference="right_back_wheel">
    <mu1 value="200.0"/>
    <mu2 value="100.0"/>
    <kp value="10000000.0"/>
    <kd value="1.0"/>
    <material>Gazebo/Black</material>
  </gazebo>
  <transmission name="right_back_wheel_trans">
    <type>transmission_interface/SimpleTransmission</type>
    <joint name="right_back_wheel_joint">
      <hardwareInterface>VelocityJointInterface</hardwareInterface>
    </joint>
    <actuator name="right_back_wheel_motor">
      <mechanicalReduction>1</mechanicalReduction>
    </actuator>
  </transmission>
  <link name="right_back_wheel">
    <collision>
      <geometry>
        <cylinder radius="0.127" length="0.0889"/>
      </geometry>
      <origin rpy="1.57075 0 0" xyz="0 0 0"/>
    </collision>
    <visual>
      <geometry>
        <cylinder radius="0.127" length="0.0889"/>
      </geometry>
      <origin rpy="1.57075 0 0" xyz="0 0 0"/>
      <material name="black"/>
    </visual>
    <inertial>
      <mass value="1"/>
      <inertia ixx="1.0" ixy="0.0" ixz="0.0" iyy="1.0" iyz="0.0" izz="1.0"/>
    </inertial>
  </link>
  <joint name="right_back_wheel_joint" type="continuous">
    <axis rpy="0 0 0" xyz="0 1 0"/>
    <parent link="base_link"/>
    <child link="right_back_wheel"/>
    <origin xyz="-0.23 -0.2286 0.0"/>
  </joint>

<!--IMU : joint , link , sensor  -->
 <joint name="imu_joint" type="fixed">
    <axis xyz="1 0 0"/>      
    <origin xyz="0 0 0.105"/>
    <parent link="base_link"/>
    <child link="imu_link"/>
  </joint>
<link name="imu_link">
  <inertial>
    <mass value="0.001"/>
    <origin rpy="0 0 0" xyz="0 0 0"/>
    <inertia ixx="0.0001" ixy="0" ixz="0" iyy="0.000001" iyz="0" izz="0.0001"/>
  </inertial>
  <visual>
    <origin rpy="0 0 0" xyz="0 0 0"/>
    <geometry>
      <box size="0.01 0.01 0.01"/>
    </geometry>
    <material name="red"/>  
  </visual>
  <collision>
    <origin rpy="0 0 0" xyz="0 0 0"/>
    <geometry>
      <box size=".01 .01 .01"/>
    </geometry>
  </collision>
</link>

  <!-- Gazebo plugin for ROS Control -->
<gazebo>
  <plugin name="gazebo_ros_control" filename="libgazebo_ros_control.so">
    <robotNamespace>/titan</robotNamespace>
  </plugin>
</gazebo>

  <!-- Import sensors -->
  <!-- Add stero-vision camera -->
  <!-- https://github.com/jhu-lcsr/lcsr_camera_models/blob/master/stereo_camera.urdf.xacro -->
  <!-- http://gazebosim.org/tutorials?tut=ros_gzplugins&cat=connect_ros -->
  <gazebo reference="camera_frame_link">
    <sensor name="stereo_camera" type="multicamera">
      <update_rate>30.0</update_rate>
      <camera name="left">
        <pose>0 0.05 0 0 0 0</pose>
        <horizontal_fov>1.3962634</horizontal_fov>
        <image>
          <width>800</width>
          <height>800</height>
          <format>R8G8B8</format>
        </image>
        <clip>
          <near>0.05</near>
          <far>300</far>
        </clip>
        <noise>
          <type>gaussian</type>
          <mean>0.0</mean>
          <stddev>0.007</stddev>
        </noise>
      </camera>
      <camera name="right">
        <pose>0 -0.05 0 0 0 0</pose>
        <horizontal_fov>1.3962634</horizontal_fov>
        <image>
          <width>800</width>
          <height>800</height>
          <format>R8G8B8</format>
        </image>
        <clip>
          <near>0.05</near>
          <far>300</far>
        </clip>
        <noise>
          <type>gaussian</type>
          <mean>0.0</mean>
          <stddev>0.007</stddev>
        </noise>
      </camera>
      <plugin filename="libgazebo_ros_multicamera.so" name="stereo_camera_controller">
        <alwaysOn>true</alwaysOn>
        <updateRate>20.0</updateRate>
        <cameraName>snoobot/stereo_camera/</cameraName>
        <imageTopicName>image_raw</imageTopicName>
        <cameraInfoTopicName>camera_info</cameraInfoTopicName>
        <frameName>camera_frame_link</frameName>
        <hackBaseline>0.07</hackBaseline>
        <distortionK1>0.0</distortionK1>
        <distortionK2>0.0</distortionK2>
        <distortionK3>0.0</distortionK3>
        <distortionT1>0.0</distortionT1>
        <distortionT2>0.0</distortionT2>
      </plugin>
    </sensor>
  </gazebo>
  <!-- Range sensor on stereo-camera -->
  <gazebo reference="camera_frame_link">
    <sensor name="sonar" type="ray">
      <ray>
        <scan>
          <horizontal>
            <samples>1</samples>
            <resolution>1.0</resolution>
            <min_angle>-0.01</min_angle>
            <max_angle>0.01</max_angle>
          </horizontal>
          <vertical>
            <samples>1</samples>
            <resolution>1</resolution>
            <min_angle>-0.01</min_angle>
            <max_angle>0.01</max_angle>
          </vertical>
        </scan>
        <range>
          <min>0.2</min>
          <max>20.00</max>
          <resolution>0.01</resolution>
        </range>
      </ray>
      <plugin filename="libgazebo_ros_range.so" name="gazebo_ros_range">
        <gaussianNoise>0.005</gaussianNoise>
        <alwaysOn>true</alwaysOn>
        <updateRate>10</updateRate>
        <topicName>snoobot/sonar_camera</topicName>
        <frameName>camera_frame_link</frameName>
        <fov>0.1</fov>
        <radiation>ultrasound</radiation>
      </plugin>
    </sensor>
  </gazebo>

<!-- Add BFF IMU sensor >
<gazebo>
  <sensor name="bff_imu_sensor" type="imu">
    <always_on>1</always_on>
    <update_rate>1000.0</update_rate>
    <imu>
      <noise>
        <type>gaussian</type>
        <rate>
          <mean>0.0</mean>
          <stddev>2e-4</stddev>
          <bias_mean>0.0000075</bias_mean>
          <bias_stddev>0.0000008</bias_stddev>
        </rate>
        <accel>
          <mean>0.0</mean>
          <stddev>1.7e-2</stddev>
          <bias_mean>0.1</bias_mean>
          <bias_stddev>0.001</bias_stddev>
        </accel>
      </noise>
    </imu>
  </sensor>
  <plugin filename="libgazebo_ros_imu.so" name="imu_plugin">
    <alwaysOn>true</alwaysOn>
    <bodyName>base_link</bodyName>
    <topicName>titan/imu_data</topicName>
    <serviceName>titan/imu_service</serviceName>
    <gaussianNoise>0.003</gaussianNoise>
    <updateRate>100.0</updateRate>
  </plugin>
</gazebo-->

<!-- Add BFF IMU sensor -->
<gazebo>    
    <plugin name="imu_plugin" filename="libgazebo_ros_imu.so">
        <alwaysOn>true</alwaysOn>       
        <bodyName>imu_link</bodyName>
        <topicName>imu_data</topicName>
        <serviceName>imu_service</serviceName>
        <gaussianNoise>1.0</gaussianNoise>
        <updateRate>10.0</updateRate> 
    </plugin>
</gazebo>

<!-- Add BFF IMU sensor -->
<gazebo>
  <plugin name="differential_drive_controller" filename="libdiffdrive_plugin.so">
    <alwaysOn>true</alwaysOn>
    <updateRate>5</updateRate>
    <leftJoint>right_front_wheel_joint</leftJoint>
    <rightJoint>left_front_wheel_joint</rightJoint>
    <wheelSeparation>0.5380</wheelSeparation>
    <wheelDiameter>0.2410</wheelDiameter>
    <torque>20</torque>
    <commandTopic>cmd_vel</commandTopic>
    <odometryTopic>odom</odometryTopic>
    <odometryFrame>odom</odometryFrame>
    <robotBaseFrame>base_footprint</robotBaseFrame>
  </plugin>
</gazebo>



</robot>
